################################################################################
 
2019-06-25 09:29:22.380673
 
Error on line 250:
 single positional indexer is out-of-bounds
 
Traceback (most recent call last):
  File "c:\Users\hiltonc\Desktop\failure\src\a05shap.py", line 250, in <module>
  File "C:\Miniconda3\envs\ml01\lib\site-packages\pandas\core\indexing.py", line 1494, in __getitem__
    return self._getitem_tuple(key)
  File "C:\Miniconda3\envs\ml01\lib\site-packages\pandas\core\indexing.py", line 2143, in _getitem_tuple
    self._has_valid_tuple(tup)
  File "C:\Miniconda3\envs\ml01\lib\site-packages\pandas\core\indexing.py", line 223, in _has_valid_tuple
    self._validate_key(k, i)
  File "C:\Miniconda3\envs\ml01\lib\site-packages\pandas\core\indexing.py", line 2070, in _validate_key
    self._validate_integer(key, axis)
  File "C:\Miniconda3\envs\ml01\lib\site-packages\pandas\core\indexing.py", line 2139, in _validate_integer
    raise IndexError("single positional indexer is out-of-bounds")
IndexError: single positional indexer is out-of-bounds

################################################################################
 
################################################################################
 
2019-06-25 09:29:23.219595
 
Error on line 250:
 single positional indexer is out-of-bounds
 
Traceback (most recent call last):
  File "c:\Users\hiltonc\Desktop\failure\src\a05shap.py", line 250, in <module>
  File "C:\Miniconda3\envs\ml01\lib\site-packages\pandas\core\indexing.py", line 1494, in __getitem__
    return self._getitem_tuple(key)
  File "C:\Miniconda3\envs\ml01\lib\site-packages\pandas\core\indexing.py", line 2143, in _getitem_tuple
    self._has_valid_tuple(tup)
  File "C:\Miniconda3\envs\ml01\lib\site-packages\pandas\core\indexing.py", line 223, in _has_valid_tuple
    self._validate_key(k, i)
  File "C:\Miniconda3\envs\ml01\lib\site-packages\pandas\core\indexing.py", line 2070, in _validate_key
    self._validate_integer(key, axis)
  File "C:\Miniconda3\envs\ml01\lib\site-packages\pandas\core\indexing.py", line 2139, in _validate_integer
    raise IndexError("single positional indexer is out-of-bounds")
IndexError: single positional indexer is out-of-bounds

################################################################################
 
################################################################################
 
2019-06-25 09:29:23.968662
 
Error on line 250:
 single positional indexer is out-of-bounds
 
Traceback (most recent call last):
  File "c:\Users\hiltonc\Desktop\failure\src\a05shap.py", line 250, in <module>
  File "C:\Miniconda3\envs\ml01\lib\site-packages\pandas\core\indexing.py", line 1494, in __getitem__
    return self._getitem_tuple(key)
  File "C:\Miniconda3\envs\ml01\lib\site-packages\pandas\core\indexing.py", line 2143, in _getitem_tuple
    self._has_valid_tuple(tup)
  File "C:\Miniconda3\envs\ml01\lib\site-packages\pandas\core\indexing.py", line 223, in _has_valid_tuple
    self._validate_key(k, i)
  File "C:\Miniconda3\envs\ml01\lib\site-packages\pandas\core\indexing.py", line 2070, in _validate_key
    self._validate_integer(key, axis)
  File "C:\Miniconda3\envs\ml01\lib\site-packages\pandas\core\indexing.py", line 2139, in _validate_integer
    raise IndexError("single positional indexer is out-of-bounds")
IndexError: single positional indexer is out-of-bounds

################################################################################
 
################################################################################
 
2019-06-25 09:29:25.497238
 
Error on line 250:
 single positional indexer is out-of-bounds
 
Traceback (most recent call last):
  File "c:\Users\hiltonc\Desktop\failure\src\a05shap.py", line 250, in <module>
  File "C:\Miniconda3\envs\ml01\lib\site-packages\pandas\core\indexing.py", line 1494, in __getitem__
    return self._getitem_tuple(key)
  File "C:\Miniconda3\envs\ml01\lib\site-packages\pandas\core\indexing.py", line 2143, in _getitem_tuple
    self._has_valid_tuple(tup)
  File "C:\Miniconda3\envs\ml01\lib\site-packages\pandas\core\indexing.py", line 223, in _has_valid_tuple
    self._validate_key(k, i)
  File "C:\Miniconda3\envs\ml01\lib\site-packages\pandas\core\indexing.py", line 2070, in _validate_key
    self._validate_integer(key, axis)
  File "C:\Miniconda3\envs\ml01\lib\site-packages\pandas\core\indexing.py", line 2139, in _validate_integer
    raise IndexError("single positional indexer is out-of-bounds")
IndexError: single positional indexer is out-of-bounds

################################################################################
 
################################################################################
 
2019-06-25 09:29:25.500166
 
Error on line 250:
 single positional indexer is out-of-bounds
 
Traceback (most recent call last):
  File "c:\Users\hiltonc\Desktop\failure\src\a05shap.py", line 250, in <module>
  File "C:\Miniconda3\envs\ml01\lib\site-packages\pandas\core\indexing.py", line 1494, in __getitem__
    return self._getitem_tuple(key)
  File "C:\Miniconda3\envs\ml01\lib\site-packages\pandas\core\indexing.py", line 2143, in _getitem_tuple
    self._has_valid_tuple(tup)
  File "C:\Miniconda3\envs\ml01\lib\site-packages\pandas\core\indexing.py", line 223, in _has_valid_tuple
    self._validate_key(k, i)
  File "C:\Miniconda3\envs\ml01\lib\site-packages\pandas\core\indexing.py", line 2070, in _validate_key
    self._validate_integer(key, axis)
  File "C:\Miniconda3\envs\ml01\lib\site-packages\pandas\core\indexing.py", line 2139, in _validate_integer
    raise IndexError("single positional indexer is out-of-bounds")
IndexError: single positional indexer is out-of-bounds

################################################################################
 
################################################################################
 
2019-06-25 09:29:25.502118
 
Error on line 250:
 single positional indexer is out-of-bounds
 
Traceback (most recent call last):
  File "c:\Users\hiltonc\Desktop\failure\src\a05shap.py", line 250, in <module>
  File "C:\Miniconda3\envs\ml01\lib\site-packages\pandas\core\indexing.py", line 1494, in __getitem__
    return self._getitem_tuple(key)
  File "C:\Miniconda3\envs\ml01\lib\site-packages\pandas\core\indexing.py", line 2143, in _getitem_tuple
    self._has_valid_tuple(tup)
  File "C:\Miniconda3\envs\ml01\lib\site-packages\pandas\core\indexing.py", line 223, in _has_valid_tuple
    self._validate_key(k, i)
  File "C:\Miniconda3\envs\ml01\lib\site-packages\pandas\core\indexing.py", line 2070, in _validate_key
    self._validate_integer(key, axis)
  File "C:\Miniconda3\envs\ml01\lib\site-packages\pandas\core\indexing.py", line 2139, in _validate_integer
    raise IndexError("single positional indexer is out-of-bounds")
IndexError: single positional indexer is out-of-bounds

################################################################################
 
################################################################################
 
2019-06-25 09:29:25.503093
 
Error on line 250:
 single positional indexer is out-of-bounds
 
Traceback (most recent call last):
  File "c:\Users\hiltonc\Desktop\failure\src\a05shap.py", line 250, in <module>
  File "C:\Miniconda3\envs\ml01\lib\site-packages\pandas\core\indexing.py", line 1494, in __getitem__
    return self._getitem_tuple(key)
  File "C:\Miniconda3\envs\ml01\lib\site-packages\pandas\core\indexing.py", line 2143, in _getitem_tuple
    self._has_valid_tuple(tup)
  File "C:\Miniconda3\envs\ml01\lib\site-packages\pandas\core\indexing.py", line 223, in _has_valid_tuple
    self._validate_key(k, i)
  File "C:\Miniconda3\envs\ml01\lib\site-packages\pandas\core\indexing.py", line 2070, in _validate_key
    self._validate_integer(key, axis)
  File "C:\Miniconda3\envs\ml01\lib\site-packages\pandas\core\indexing.py", line 2139, in _validate_integer
    raise IndexError("single positional indexer is out-of-bounds")
IndexError: single positional indexer is out-of-bounds

################################################################################
 
################################################################################
 
2019-06-25 09:29:25.505046
 
Error on line 250:
 single positional indexer is out-of-bounds
 
Traceback (most recent call last):
  File "c:\Users\hiltonc\Desktop\failure\src\a05shap.py", line 250, in <module>
  File "C:\Miniconda3\envs\ml01\lib\site-packages\pandas\core\indexing.py", line 1494, in __getitem__
    return self._getitem_tuple(key)
  File "C:\Miniconda3\envs\ml01\lib\site-packages\pandas\core\indexing.py", line 2143, in _getitem_tuple
    self._has_valid_tuple(tup)
  File "C:\Miniconda3\envs\ml01\lib\site-packages\pandas\core\indexing.py", line 223, in _has_valid_tuple
    self._validate_key(k, i)
  File "C:\Miniconda3\envs\ml01\lib\site-packages\pandas\core\indexing.py", line 2070, in _validate_key
    self._validate_integer(key, axis)
  File "C:\Miniconda3\envs\ml01\lib\site-packages\pandas\core\indexing.py", line 2139, in _validate_integer
    raise IndexError("single positional indexer is out-of-bounds")
IndexError: single positional indexer is out-of-bounds

################################################################################
 
################################################################################
 
2019-06-25 09:29:27.159848
 
Error on line 250:
 single positional indexer is out-of-bounds
 
Traceback (most recent call last):
  File "c:\Users\hiltonc\Desktop\failure\src\a05shap.py", line 250, in <module>
  File "C:\Miniconda3\envs\ml01\lib\site-packages\pandas\core\indexing.py", line 1494, in __getitem__
    return self._getitem_tuple(key)
  File "C:\Miniconda3\envs\ml01\lib\site-packages\pandas\core\indexing.py", line 2143, in _getitem_tuple
    self._has_valid_tuple(tup)
  File "C:\Miniconda3\envs\ml01\lib\site-packages\pandas\core\indexing.py", line 223, in _has_valid_tuple
    self._validate_key(k, i)
  File "C:\Miniconda3\envs\ml01\lib\site-packages\pandas\core\indexing.py", line 2070, in _validate_key
    self._validate_integer(key, axis)
  File "C:\Miniconda3\envs\ml01\lib\site-packages\pandas\core\indexing.py", line 2139, in _validate_integer
    raise IndexError("single positional indexer is out-of-bounds")
IndexError: single positional indexer is out-of-bounds

################################################################################
 
################################################################################
 
2019-06-25 09:29:29.001254
 
Error on line 250:
 single positional indexer is out-of-bounds
 
Traceback (most recent call last):
  File "c:\Users\hiltonc\Desktop\failure\src\a05shap.py", line 250, in <module>
  File "C:\Miniconda3\envs\ml01\lib\site-packages\pandas\core\indexing.py", line 1494, in __getitem__
    return self._getitem_tuple(key)
  File "C:\Miniconda3\envs\ml01\lib\site-packages\pandas\core\indexing.py", line 2143, in _getitem_tuple
    self._has_valid_tuple(tup)
  File "C:\Miniconda3\envs\ml01\lib\site-packages\pandas\core\indexing.py", line 223, in _has_valid_tuple
    self._validate_key(k, i)
  File "C:\Miniconda3\envs\ml01\lib\site-packages\pandas\core\indexing.py", line 2070, in _validate_key
    self._validate_integer(key, axis)
  File "C:\Miniconda3\envs\ml01\lib\site-packages\pandas\core\indexing.py", line 2139, in _validate_integer
    raise IndexError("single positional indexer is out-of-bounds")
IndexError: single positional indexer is out-of-bounds

################################################################################
 
################################################################################
 
2019-06-25 09:29:29.790255
 
Error on line 250:
 single positional indexer is out-of-bounds
 
Traceback (most recent call last):
  File "c:\Users\hiltonc\Desktop\failure\src\a05shap.py", line 250, in <module>
  File "C:\Miniconda3\envs\ml01\lib\site-packages\pandas\core\indexing.py", line 1494, in __getitem__
    return self._getitem_tuple(key)
  File "C:\Miniconda3\envs\ml01\lib\site-packages\pandas\core\indexing.py", line 2143, in _getitem_tuple
    self._has_valid_tuple(tup)
  File "C:\Miniconda3\envs\ml01\lib\site-packages\pandas\core\indexing.py", line 223, in _has_valid_tuple
    self._validate_key(k, i)
  File "C:\Miniconda3\envs\ml01\lib\site-packages\pandas\core\indexing.py", line 2070, in _validate_key
    self._validate_integer(key, axis)
  File "C:\Miniconda3\envs\ml01\lib\site-packages\pandas\core\indexing.py", line 2139, in _validate_integer
    raise IndexError("single positional indexer is out-of-bounds")
IndexError: single positional indexer is out-of-bounds

################################################################################
 
################################################################################
 
2019-06-25 09:30:21.845602
 
Error on line 250:
 single positional indexer is out-of-bounds
 
Traceback (most recent call last):
  File "c:\Users\hiltonc\Desktop\failure\src\a05shap.py", line 250, in <module>
  File "C:\Miniconda3\envs\ml01\lib\site-packages\pandas\core\indexing.py", line 1494, in __getitem__
    return self._getitem_tuple(key)
  File "C:\Miniconda3\envs\ml01\lib\site-packages\pandas\core\indexing.py", line 2143, in _getitem_tuple
    self._has_valid_tuple(tup)
  File "C:\Miniconda3\envs\ml01\lib\site-packages\pandas\core\indexing.py", line 223, in _has_valid_tuple
    self._validate_key(k, i)
  File "C:\Miniconda3\envs\ml01\lib\site-packages\pandas\core\indexing.py", line 2070, in _validate_key
    self._validate_integer(key, axis)
  File "C:\Miniconda3\envs\ml01\lib\site-packages\pandas\core\indexing.py", line 2139, in _validate_integer
    raise IndexError("single positional indexer is out-of-bounds")
IndexError: single positional indexer is out-of-bounds

################################################################################
 
################################################################################
 
2019-06-25 09:30:22.366454
 
Error on line 250:
 single positional indexer is out-of-bounds
 
Traceback (most recent call last):
  File "c:\Users\hiltonc\Desktop\failure\src\a05shap.py", line 250, in <module>
  File "C:\Miniconda3\envs\ml01\lib\site-packages\pandas\core\indexing.py", line 1494, in __getitem__
    return self._getitem_tuple(key)
  File "C:\Miniconda3\envs\ml01\lib\site-packages\pandas\core\indexing.py", line 2143, in _getitem_tuple
    self._has_valid_tuple(tup)
  File "C:\Miniconda3\envs\ml01\lib\site-packages\pandas\core\indexing.py", line 223, in _has_valid_tuple
    self._validate_key(k, i)
  File "C:\Miniconda3\envs\ml01\lib\site-packages\pandas\core\indexing.py", line 2070, in _validate_key
    self._validate_integer(key, axis)
  File "C:\Miniconda3\envs\ml01\lib\site-packages\pandas\core\indexing.py", line 2139, in _validate_integer
    raise IndexError("single positional indexer is out-of-bounds")
IndexError: single positional indexer is out-of-bounds

################################################################################
 
################################################################################
 
2019-06-25 09:30:22.928365
 
Error on line 250:
 single positional indexer is out-of-bounds
 
Traceback (most recent call last):
  File "c:\Users\hiltonc\Desktop\failure\src\a05shap.py", line 250, in <module>
  File "C:\Miniconda3\envs\ml01\lib\site-packages\pandas\core\indexing.py", line 1494, in __getitem__
    return self._getitem_tuple(key)
  File "C:\Miniconda3\envs\ml01\lib\site-packages\pandas\core\indexing.py", line 2143, in _getitem_tuple
    self._has_valid_tuple(tup)
  File "C:\Miniconda3\envs\ml01\lib\site-packages\pandas\core\indexing.py", line 223, in _has_valid_tuple
    self._validate_key(k, i)
  File "C:\Miniconda3\envs\ml01\lib\site-packages\pandas\core\indexing.py", line 2070, in _validate_key
    self._validate_integer(key, axis)
  File "C:\Miniconda3\envs\ml01\lib\site-packages\pandas\core\indexing.py", line 2139, in _validate_integer
    raise IndexError("single positional indexer is out-of-bounds")
IndexError: single positional indexer is out-of-bounds

################################################################################
 
################################################################################
 
2019-06-25 09:30:23.543922
 
Error on line 250:
 single positional indexer is out-of-bounds
 
Traceback (most recent call last):
  File "c:\Users\hiltonc\Desktop\failure\src\a05shap.py", line 250, in <module>
  File "C:\Miniconda3\envs\ml01\lib\site-packages\pandas\core\indexing.py", line 1494, in __getitem__
    return self._getitem_tuple(key)
  File "C:\Miniconda3\envs\ml01\lib\site-packages\pandas\core\indexing.py", line 2143, in _getitem_tuple
    self._has_valid_tuple(tup)
  File "C:\Miniconda3\envs\ml01\lib\site-packages\pandas\core\indexing.py", line 223, in _has_valid_tuple
    self._validate_key(k, i)
  File "C:\Miniconda3\envs\ml01\lib\site-packages\pandas\core\indexing.py", line 2070, in _validate_key
    self._validate_integer(key, axis)
  File "C:\Miniconda3\envs\ml01\lib\site-packages\pandas\core\indexing.py", line 2139, in _validate_integer
    raise IndexError("single positional indexer is out-of-bounds")
IndexError: single positional indexer is out-of-bounds

################################################################################
 
################################################################################
 
2019-06-25 09:30:23.545843
 
Error on line 250:
 single positional indexer is out-of-bounds
 
Traceback (most recent call last):
  File "c:\Users\hiltonc\Desktop\failure\src\a05shap.py", line 250, in <module>
  File "C:\Miniconda3\envs\ml01\lib\site-packages\pandas\core\indexing.py", line 1494, in __getitem__
    return self._getitem_tuple(key)
  File "C:\Miniconda3\envs\ml01\lib\site-packages\pandas\core\indexing.py", line 2143, in _getitem_tuple
    self._has_valid_tuple(tup)
  File "C:\Miniconda3\envs\ml01\lib\site-packages\pandas\core\indexing.py", line 223, in _has_valid_tuple
    self._validate_key(k, i)
  File "C:\Miniconda3\envs\ml01\lib\site-packages\pandas\core\indexing.py", line 2070, in _validate_key
    self._validate_integer(key, axis)
  File "C:\Miniconda3\envs\ml01\lib\site-packages\pandas\core\indexing.py", line 2139, in _validate_integer
    raise IndexError("single positional indexer is out-of-bounds")
IndexError: single positional indexer is out-of-bounds

################################################################################
 
################################################################################
 
2019-06-25 09:30:23.546819
 
Error on line 250:
 single positional indexer is out-of-bounds
 
Traceback (most recent call last):
  File "c:\Users\hiltonc\Desktop\failure\src\a05shap.py", line 250, in <module>
  File "C:\Miniconda3\envs\ml01\lib\site-packages\pandas\core\indexing.py", line 1494, in __getitem__
    return self._getitem_tuple(key)
  File "C:\Miniconda3\envs\ml01\lib\site-packages\pandas\core\indexing.py", line 2143, in _getitem_tuple
    self._has_valid_tuple(tup)
  File "C:\Miniconda3\envs\ml01\lib\site-packages\pandas\core\indexing.py", line 223, in _has_valid_tuple
    self._validate_key(k, i)
  File "C:\Miniconda3\envs\ml01\lib\site-packages\pandas\core\indexing.py", line 2070, in _validate_key
    self._validate_integer(key, axis)
  File "C:\Miniconda3\envs\ml01\lib\site-packages\pandas\core\indexing.py", line 2139, in _validate_integer
    raise IndexError("single positional indexer is out-of-bounds")
IndexError: single positional indexer is out-of-bounds

################################################################################
 
################################################################################
 
2019-06-25 09:30:23.547838
 
Error on line 250:
 single positional indexer is out-of-bounds
 
Traceback (most recent call last):
  File "c:\Users\hiltonc\Desktop\failure\src\a05shap.py", line 250, in <module>
  File "C:\Miniconda3\envs\ml01\lib\site-packages\pandas\core\indexing.py", line 1494, in __getitem__
    return self._getitem_tuple(key)
  File "C:\Miniconda3\envs\ml01\lib\site-packages\pandas\core\indexing.py", line 2143, in _getitem_tuple
    self._has_valid_tuple(tup)
  File "C:\Miniconda3\envs\ml01\lib\site-packages\pandas\core\indexing.py", line 223, in _has_valid_tuple
    self._validate_key(k, i)
  File "C:\Miniconda3\envs\ml01\lib\site-packages\pandas\core\indexing.py", line 2070, in _validate_key
    self._validate_integer(key, axis)
  File "C:\Miniconda3\envs\ml01\lib\site-packages\pandas\core\indexing.py", line 2139, in _validate_integer
    raise IndexError("single positional indexer is out-of-bounds")
IndexError: single positional indexer is out-of-bounds

################################################################################
 
################################################################################
 
2019-06-25 09:30:23.549747
 
Error on line 250:
 single positional indexer is out-of-bounds
 
Traceback (most recent call last):
  File "c:\Users\hiltonc\Desktop\failure\src\a05shap.py", line 250, in <module>
  File "C:\Miniconda3\envs\ml01\lib\site-packages\pandas\core\indexing.py", line 1494, in __getitem__
    return self._getitem_tuple(key)
  File "C:\Miniconda3\envs\ml01\lib\site-packages\pandas\core\indexing.py", line 2143, in _getitem_tuple
    self._has_valid_tuple(tup)
  File "C:\Miniconda3\envs\ml01\lib\site-packages\pandas\core\indexing.py", line 223, in _has_valid_tuple
    self._validate_key(k, i)
  File "C:\Miniconda3\envs\ml01\lib\site-packages\pandas\core\indexing.py", line 2070, in _validate_key
    self._validate_integer(key, axis)
  File "C:\Miniconda3\envs\ml01\lib\site-packages\pandas\core\indexing.py", line 2139, in _validate_integer
    raise IndexError("single positional indexer is out-of-bounds")
IndexError: single positional indexer is out-of-bounds

################################################################################
 
################################################################################
 
2019-06-25 09:30:24.652752
 
Error on line 250:
 single positional indexer is out-of-bounds
 
Traceback (most recent call last):
  File "c:\Users\hiltonc\Desktop\failure\src\a05shap.py", line 250, in <module>
  File "C:\Miniconda3\envs\ml01\lib\site-packages\pandas\core\indexing.py", line 1494, in __getitem__
    return self._getitem_tuple(key)
  File "C:\Miniconda3\envs\ml01\lib\site-packages\pandas\core\indexing.py", line 2143, in _getitem_tuple
    self._has_valid_tuple(tup)
  File "C:\Miniconda3\envs\ml01\lib\site-packages\pandas\core\indexing.py", line 223, in _has_valid_tuple
    self._validate_key(k, i)
  File "C:\Miniconda3\envs\ml01\lib\site-packages\pandas\core\indexing.py", line 2070, in _validate_key
    self._validate_integer(key, axis)
  File "C:\Miniconda3\envs\ml01\lib\site-packages\pandas\core\indexing.py", line 2139, in _validate_integer
    raise IndexError("single positional indexer is out-of-bounds")
IndexError: single positional indexer is out-of-bounds

################################################################################
 
################################################################################
 
2019-06-25 09:30:26.415077
 
Error on line 250:
 single positional indexer is out-of-bounds
 
Traceback (most recent call last):
  File "c:\Users\hiltonc\Desktop\failure\src\a05shap.py", line 250, in <module>
  File "C:\Miniconda3\envs\ml01\lib\site-packages\pandas\core\indexing.py", line 1494, in __getitem__
    return self._getitem_tuple(key)
  File "C:\Miniconda3\envs\ml01\lib\site-packages\pandas\core\indexing.py", line 2143, in _getitem_tuple
    self._has_valid_tuple(tup)
  File "C:\Miniconda3\envs\ml01\lib\site-packages\pandas\core\indexing.py", line 223, in _has_valid_tuple
    self._validate_key(k, i)
  File "C:\Miniconda3\envs\ml01\lib\site-packages\pandas\core\indexing.py", line 2070, in _validate_key
    self._validate_integer(key, axis)
  File "C:\Miniconda3\envs\ml01\lib\site-packages\pandas\core\indexing.py", line 2139, in _validate_integer
    raise IndexError("single positional indexer is out-of-bounds")
IndexError: single positional indexer is out-of-bounds

################################################################################
 
################################################################################
 
2019-06-25 09:30:27.042972
 
Error on line 250:
 single positional indexer is out-of-bounds
 
Traceback (most recent call last):
  File "c:\Users\hiltonc\Desktop\failure\src\a05shap.py", line 250, in <module>
  File "C:\Miniconda3\envs\ml01\lib\site-packages\pandas\core\indexing.py", line 1494, in __getitem__
    return self._getitem_tuple(key)
  File "C:\Miniconda3\envs\ml01\lib\site-packages\pandas\core\indexing.py", line 2143, in _getitem_tuple
    self._has_valid_tuple(tup)
  File "C:\Miniconda3\envs\ml01\lib\site-packages\pandas\core\indexing.py", line 223, in _has_valid_tuple
    self._validate_key(k, i)
  File "C:\Miniconda3\envs\ml01\lib\site-packages\pandas\core\indexing.py", line 2070, in _validate_key
    self._validate_integer(key, axis)
  File "C:\Miniconda3\envs\ml01\lib\site-packages\pandas\core\indexing.py", line 2139, in _validate_integer
    raise IndexError("single positional indexer is out-of-bounds")
IndexError: single positional indexer is out-of-bounds

################################################################################
 
################################################################################
 
2019-06-25 09:31:19.663537
 
Error on line 250:
 single positional indexer is out-of-bounds
 
Traceback (most recent call last):
  File "c:\Users\hiltonc\Desktop\failure\src\a05shap.py", line 250, in <module>
  File "C:\Miniconda3\envs\ml01\lib\site-packages\pandas\core\indexing.py", line 1494, in __getitem__
    return self._getitem_tuple(key)
  File "C:\Miniconda3\envs\ml01\lib\site-packages\pandas\core\indexing.py", line 2143, in _getitem_tuple
    self._has_valid_tuple(tup)
  File "C:\Miniconda3\envs\ml01\lib\site-packages\pandas\core\indexing.py", line 223, in _has_valid_tuple
    self._validate_key(k, i)
  File "C:\Miniconda3\envs\ml01\lib\site-packages\pandas\core\indexing.py", line 2070, in _validate_key
    self._validate_integer(key, axis)
  File "C:\Miniconda3\envs\ml01\lib\site-packages\pandas\core\indexing.py", line 2139, in _validate_integer
    raise IndexError("single positional indexer is out-of-bounds")
IndexError: single positional indexer is out-of-bounds

################################################################################
 
################################################################################
 
2019-06-25 09:31:20.397534
 
Error on line 250:
 single positional indexer is out-of-bounds
 
Traceback (most recent call last):
  File "c:\Users\hiltonc\Desktop\failure\src\a05shap.py", line 250, in <module>
  File "C:\Miniconda3\envs\ml01\lib\site-packages\pandas\core\indexing.py", line 1494, in __getitem__
    return self._getitem_tuple(key)
  File "C:\Miniconda3\envs\ml01\lib\site-packages\pandas\core\indexing.py", line 2143, in _getitem_tuple
    self._has_valid_tuple(tup)
  File "C:\Miniconda3\envs\ml01\lib\site-packages\pandas\core\indexing.py", line 223, in _has_valid_tuple
    self._validate_key(k, i)
  File "C:\Miniconda3\envs\ml01\lib\site-packages\pandas\core\indexing.py", line 2070, in _validate_key
    self._validate_integer(key, axis)
  File "C:\Miniconda3\envs\ml01\lib\site-packages\pandas\core\indexing.py", line 2139, in _validate_integer
    raise IndexError("single positional indexer is out-of-bounds")
IndexError: single positional indexer is out-of-bounds

################################################################################
 
################################################################################
 
2019-06-25 09:31:21.054024
 
Error on line 250:
 single positional indexer is out-of-bounds
 
Traceback (most recent call last):
  File "c:\Users\hiltonc\Desktop\failure\src\a05shap.py", line 250, in <module>
  File "C:\Miniconda3\envs\ml01\lib\site-packages\pandas\core\indexing.py", line 1494, in __getitem__
    return self._getitem_tuple(key)
  File "C:\Miniconda3\envs\ml01\lib\site-packages\pandas\core\indexing.py", line 2143, in _getitem_tuple
    self._has_valid_tuple(tup)
  File "C:\Miniconda3\envs\ml01\lib\site-packages\pandas\core\indexing.py", line 223, in _has_valid_tuple
    self._validate_key(k, i)
  File "C:\Miniconda3\envs\ml01\lib\site-packages\pandas\core\indexing.py", line 2070, in _validate_key
    self._validate_integer(key, axis)
  File "C:\Miniconda3\envs\ml01\lib\site-packages\pandas\core\indexing.py", line 2139, in _validate_integer
    raise IndexError("single positional indexer is out-of-bounds")
IndexError: single positional indexer is out-of-bounds

################################################################################
 
################################################################################
 
2019-06-25 09:31:21.888656
 
Error on line 250:
 single positional indexer is out-of-bounds
 
Traceback (most recent call last):
  File "c:\Users\hiltonc\Desktop\failure\src\a05shap.py", line 250, in <module>
  File "C:\Miniconda3\envs\ml01\lib\site-packages\pandas\core\indexing.py", line 1494, in __getitem__
    return self._getitem_tuple(key)
  File "C:\Miniconda3\envs\ml01\lib\site-packages\pandas\core\indexing.py", line 2143, in _getitem_tuple
    self._has_valid_tuple(tup)
  File "C:\Miniconda3\envs\ml01\lib\site-packages\pandas\core\indexing.py", line 223, in _has_valid_tuple
    self._validate_key(k, i)
  File "C:\Miniconda3\envs\ml01\lib\site-packages\pandas\core\indexing.py", line 2070, in _validate_key
    self._validate_integer(key, axis)
  File "C:\Miniconda3\envs\ml01\lib\site-packages\pandas\core\indexing.py", line 2139, in _validate_integer
    raise IndexError("single positional indexer is out-of-bounds")
IndexError: single positional indexer is out-of-bounds

################################################################################
 
################################################################################
 
2019-06-25 09:31:21.889631
 
Error on line 250:
 single positional indexer is out-of-bounds
 
Traceback (most recent call last):
  File "c:\Users\hiltonc\Desktop\failure\src\a05shap.py", line 250, in <module>
  File "C:\Miniconda3\envs\ml01\lib\site-packages\pandas\core\indexing.py", line 1494, in __getitem__
    return self._getitem_tuple(key)
  File "C:\Miniconda3\envs\ml01\lib\site-packages\pandas\core\indexing.py", line 2143, in _getitem_tuple
    self._has_valid_tuple(tup)
  File "C:\Miniconda3\envs\ml01\lib\site-packages\pandas\core\indexing.py", line 223, in _has_valid_tuple
    self._validate_key(k, i)
  File "C:\Miniconda3\envs\ml01\lib\site-packages\pandas\core\indexing.py", line 2070, in _validate_key
    self._validate_integer(key, axis)
  File "C:\Miniconda3\envs\ml01\lib\site-packages\pandas\core\indexing.py", line 2139, in _validate_integer
    raise IndexError("single positional indexer is out-of-bounds")
IndexError: single positional indexer is out-of-bounds

################################################################################
 
################################################################################
 
2019-06-25 09:31:21.890607
 
Error on line 250:
 single positional indexer is out-of-bounds
 
Traceback (most recent call last):
  File "c:\Users\hiltonc\Desktop\failure\src\a05shap.py", line 250, in <module>
  File "C:\Miniconda3\envs\ml01\lib\site-packages\pandas\core\indexing.py", line 1494, in __getitem__
    return self._getitem_tuple(key)
  File "C:\Miniconda3\envs\ml01\lib\site-packages\pandas\core\indexing.py", line 2143, in _getitem_tuple
    self._has_valid_tuple(tup)
  File "C:\Miniconda3\envs\ml01\lib\site-packages\pandas\core\indexing.py", line 223, in _has_valid_tuple
    self._validate_key(k, i)
  File "C:\Miniconda3\envs\ml01\lib\site-packages\pandas\core\indexing.py", line 2070, in _validate_key
    self._validate_integer(key, axis)
  File "C:\Miniconda3\envs\ml01\lib\site-packages\pandas\core\indexing.py", line 2139, in _validate_integer
    raise IndexError("single positional indexer is out-of-bounds")
IndexError: single positional indexer is out-of-bounds

################################################################################
 
################################################################################
 
2019-06-25 09:31:21.892561
 
Error on line 250:
 single positional indexer is out-of-bounds
 
Traceback (most recent call last):
  File "c:\Users\hiltonc\Desktop\failure\src\a05shap.py", line 250, in <module>
  File "C:\Miniconda3\envs\ml01\lib\site-packages\pandas\core\indexing.py", line 1494, in __getitem__
    return self._getitem_tuple(key)
  File "C:\Miniconda3\envs\ml01\lib\site-packages\pandas\core\indexing.py", line 2143, in _getitem_tuple
    self._has_valid_tuple(tup)
  File "C:\Miniconda3\envs\ml01\lib\site-packages\pandas\core\indexing.py", line 223, in _has_valid_tuple
    self._validate_key(k, i)
  File "C:\Miniconda3\envs\ml01\lib\site-packages\pandas\core\indexing.py", line 2070, in _validate_key
    self._validate_integer(key, axis)
  File "C:\Miniconda3\envs\ml01\lib\site-packages\pandas\core\indexing.py", line 2139, in _validate_integer
    raise IndexError("single positional indexer is out-of-bounds")
IndexError: single positional indexer is out-of-bounds

################################################################################
 
################################################################################
 
2019-06-25 09:31:21.893623
 
Error on line 250:
 single positional indexer is out-of-bounds
 
Traceback (most recent call last):
  File "c:\Users\hiltonc\Desktop\failure\src\a05shap.py", line 250, in <module>
  File "C:\Miniconda3\envs\ml01\lib\site-packages\pandas\core\indexing.py", line 1494, in __getitem__
    return self._getitem_tuple(key)
  File "C:\Miniconda3\envs\ml01\lib\site-packages\pandas\core\indexing.py", line 2143, in _getitem_tuple
    self._has_valid_tuple(tup)
  File "C:\Miniconda3\envs\ml01\lib\site-packages\pandas\core\indexing.py", line 223, in _has_valid_tuple
    self._validate_key(k, i)
  File "C:\Miniconda3\envs\ml01\lib\site-packages\pandas\core\indexing.py", line 2070, in _validate_key
    self._validate_integer(key, axis)
  File "C:\Miniconda3\envs\ml01\lib\site-packages\pandas\core\indexing.py", line 2139, in _validate_integer
    raise IndexError("single positional indexer is out-of-bounds")
IndexError: single positional indexer is out-of-bounds

################################################################################
 
################################################################################
 
2019-06-25 09:31:23.317277
 
Error on line 250:
 single positional indexer is out-of-bounds
 
Traceback (most recent call last):
  File "c:\Users\hiltonc\Desktop\failure\src\a05shap.py", line 250, in <module>
  File "C:\Miniconda3\envs\ml01\lib\site-packages\pandas\core\indexing.py", line 1494, in __getitem__
    return self._getitem_tuple(key)
  File "C:\Miniconda3\envs\ml01\lib\site-packages\pandas\core\indexing.py", line 2143, in _getitem_tuple
    self._has_valid_tuple(tup)
  File "C:\Miniconda3\envs\ml01\lib\site-packages\pandas\core\indexing.py", line 223, in _has_valid_tuple
    self._validate_key(k, i)
  File "C:\Miniconda3\envs\ml01\lib\site-packages\pandas\core\indexing.py", line 2070, in _validate_key
    self._validate_integer(key, axis)
  File "C:\Miniconda3\envs\ml01\lib\site-packages\pandas\core\indexing.py", line 2139, in _validate_integer
    raise IndexError("single positional indexer is out-of-bounds")
IndexError: single positional indexer is out-of-bounds

################################################################################
 
################################################################################
 
2019-06-25 09:31:25.158381
 
Error on line 250:
 single positional indexer is out-of-bounds
 
Traceback (most recent call last):
  File "c:\Users\hiltonc\Desktop\failure\src\a05shap.py", line 250, in <module>
  File "C:\Miniconda3\envs\ml01\lib\site-packages\pandas\core\indexing.py", line 1494, in __getitem__
    return self._getitem_tuple(key)
  File "C:\Miniconda3\envs\ml01\lib\site-packages\pandas\core\indexing.py", line 2143, in _getitem_tuple
    self._has_valid_tuple(tup)
  File "C:\Miniconda3\envs\ml01\lib\site-packages\pandas\core\indexing.py", line 223, in _has_valid_tuple
    self._validate_key(k, i)
  File "C:\Miniconda3\envs\ml01\lib\site-packages\pandas\core\indexing.py", line 2070, in _validate_key
    self._validate_integer(key, axis)
  File "C:\Miniconda3\envs\ml01\lib\site-packages\pandas\core\indexing.py", line 2139, in _validate_integer
    raise IndexError("single positional indexer is out-of-bounds")
IndexError: single positional indexer is out-of-bounds

################################################################################
 
################################################################################
 
2019-06-25 09:31:25.912506
 
Error on line 250:
 single positional indexer is out-of-bounds
 
Traceback (most recent call last):
  File "c:\Users\hiltonc\Desktop\failure\src\a05shap.py", line 250, in <module>
  File "C:\Miniconda3\envs\ml01\lib\site-packages\pandas\core\indexing.py", line 1494, in __getitem__
    return self._getitem_tuple(key)
  File "C:\Miniconda3\envs\ml01\lib\site-packages\pandas\core\indexing.py", line 2143, in _getitem_tuple
    self._has_valid_tuple(tup)
  File "C:\Miniconda3\envs\ml01\lib\site-packages\pandas\core\indexing.py", line 223, in _has_valid_tuple
    self._validate_key(k, i)
  File "C:\Miniconda3\envs\ml01\lib\site-packages\pandas\core\indexing.py", line 2070, in _validate_key
    self._validate_integer(key, axis)
  File "C:\Miniconda3\envs\ml01\lib\site-packages\pandas\core\indexing.py", line 2139, in _validate_integer
    raise IndexError("single positional indexer is out-of-bounds")
IndexError: single positional indexer is out-of-bounds

################################################################################
 
